Workbook
Name _BQ4.1: '[1]#REF'!$A$1:$E$370
Name _BQ4.2: '[1]#REF'!$A$1:$F$43
Name _Fill: #REF!
Name _Fill: #REF!
Name _Order1: 255
Name _Ser1: IF([2]Sheet1!#REF!=1,[2]Sheet1!#REF!,[2]Sheet1!#REF!)
Name _Ser1: IF([2]Sheet1!#REF!=1,[2]Sheet1!#REF!,[2]Sheet1!#REF!)
Name _Ser2: IF([2]Sheet1!#REF!=1,[2]Sheet1!#REF!,[2]Sheet1!#REF!)
Name _Ser2: IF([2]Sheet1!#REF!=1,[2]Sheet1!#REF!,[2]Sheet1!#REF!)
Name _Ser3: IF([2]Sheet1!#REF!=1,[2]Sheet1!#REF!,[2]Sheet1!#REF!)
Name _Ser3: IF([2]Sheet1!#REF!=1,[2]Sheet1!#REF!,[2]Sheet1!#REF!)
Name _Ser4: IF([2]Sheet1!#REF!=1,[2]Sheet1!#REF!,[2]Sheet1!#REF!)
Name Account: #REF!
Name Account: #REF!
Name AccountsTM1: #REF!
Name AccountsTM1: #REF!
Name Adj: #REF!
Name Adj: #REF!
Name ADJUSTMENTS: #REF!
Name Affiliate_List: #REF!
Name All_Months: [3]Global!$L$3:$L$26
Name ASB: #REF!
Name ASB: #REF!
Name BLANK: #REF!
Name BLANK: #REF!
Name Branch: #REF!
Name BU: [4]General!$C$11
Name BU_selected_Country: [1]Macrodata!$D$13
Name BU_selected_Currency: [5]Macrodata!$E$10
Name BU_selected_w_descr: [1]Macrodata!$C$13
Name BUD: #REF!,#REF!,#REF!,#REF!,#REF!,#REF!,#REF!,#REF!,#REF!,#REF!,#REF!,#REF!,#REF!,#REF!,#REF!,#REF!,#REF!,#REF!
Name BUD: #REF!,#REF!,#REF!,#REF!,#REF!,#REF!,#REF!,#REF!,#REF!,#REF!,#REF!,#REF!,#REF!,#REF!,#REF!,#REF!,#REF!,#REF!
Name CHead: IF([2]Sheet1!#REF!=1,[2]Sheet1!#REF!,[2]Sheet1!#REF!)
Name CHead: IF([2]Sheet1!#REF!=1,[2]Sheet1!#REF!,[2]Sheet1!#REF!)
Name COMM_CONS: #REF!
Name COMM_CONS: #REF!
Name COMM_DIV: #REF!
Name COMM_DIV: #REF!
Name CONS_GLB: #REF!
Name CONS_GLB: #REF!
Name Corporate: #REF!
Name Country: [1]General!$C$11
Name Currency: [1]General!$C$12
Name Current_Month: [6]Start!$E$9
Name Data1: IF([2]Sheet1!#REF!=1,[2]Sheet1!#REF!,[2]Sheet1!#REF!)
Name Data1: IF([2]Sheet1!#REF!=1,[2]Sheet1!#REF!,[2]Sheet1!#REF!)
Name Data2: IF([2]Sheet1!#REF!=1,[2]Sheet1!#REF!,[2]Sheet1!#REF!)
Name Data2: IF([2]Sheet1!#REF!=1,[2]Sheet1!#REF!,[2]Sheet1!#REF!)
Name Data3: IF([2]Sheet1!#REF!=1,[2]Sheet1!#REF!,[2]Sheet1!#REF!)
Name Data3: IF([2]Sheet1!#REF!=1,[2]Sheet1!#REF!,[2]Sheet1!#REF!)
Name Data4: IF([2]Sheet1!#REF!=1,[2]Sheet1!#REF!,[2]Sheet1!#REF!)
Name DeptList: #REF!
Name DeptList: #REF!
Name DIVISIONAL_1K: #REF!
Name DIVISIONAL_1K: #REF!
Name Divisions: [3]Data!$U$30:$U$41
Name Divsions: #REF!
Name Divsions: #REF!
Name drop1: #REF!
Name drop1: #REF!

Sheet Individual
A1: Pack Codes | B1: January | C1: February | D1: March | E1: April | F1: May | G1: June | H1: July | I1: August | J1: September | K1: October | L1: November | M1: December | N1: Total | O1: Income Type | P1: Comments
A2: 0425100 - Non Interco Brkg Comm Renewal | B2: ='Renewal book 2026'!J171 | C2: 526071.83 | D2: 850734.25 | E2: ='Renewal book 2026'!M171 | F2: 90142.61 | G2: 483904.91 | H2: 1317800.9 | I2: ='Renewal book 2026'!Q171 | J2: 32133.87 | K2: 927417.03 | L2: 291525.47 | M2: 42412.87 | N2: =SUM(B2:M2) | O2: Renewals -Commission | P2: Linked to renewal book 2025
A3: 0425110 - Brkg Comm New Recurring | C3: 230000 | D3: 0 | E3: 0 | F3: 456683.69 | G3: 180000 | H3: 74000 | I3: 0 | J3: 748234.8 | K3: 100000 | L3: 440734.8 | M3: 234051.09 | N3: =SUM(B3:M3) | O3: New Recurring Business - Commission | P3: Linked to new business and/or cross selling
A4: 0425112 - Brkg Comm New Non-Recurring | O4: New Non Recurring Business - Commission | P4: Linked to new business and/or cross selling
A5: 0425200 - Fees - Standard | O5: Renewals - Fees
A6: 0425210 - Brkg Fees New Recurring | O6: New Recurring Business - Fees | P6: Linked to new business and/or cross selling
A7: 0425212 - Brkg Fees New Non-Recurring | O7: New Non Recurring Business - Fees | P7: Linked to new business and/or cross selling
A8: 0425300 - Fees - Other | O8: Any other Fees | P8: Linked to renewal book 2025
A10: Total | B10: =SUM(B2:B8) | C10: =SUM(C2:C8) | D10: =SUM(D2:D8) | E10: =SUM(E2:E8) | F10: =SUM(F2:F8) | G10: =SUM(G2:G8) | H10: =SUM(H2:H9) | I10: =SUM(I2:I8) | J10: =SUM(J2:J8) | K10: =SUM(K2:K8) | L10: =SUM(L2:L8) | M10: =SUM(M2:M8) | N10: =SUM(N2:N8)

Sheet Renewal book 2026
A1: CLIENT NUMBER | B1: CLIENT NAME | C1: INVOICE NO | D1: INVOICE DATE | E1: INVOICE EFF. DATE | F1: CLIENT PREMUIM | G1: BROKERAGE | H1: SPC FEE | I1: SUBAGENT | J1: January | K1: February | L1: March | M1: April | N1: May | O1: June | P1: July | Q1: August | R1: September | S1: October | T1: November | U1: December | V1: Total | W1: Ctegory
A2: A0223 | B2: Air Botswana | C2: 00297942 | D2: 45324 | E2: 45383 | F2: 14144.74 | G2: 2828.95 | H2: 0 | I2: 0 | M2: 2828.95 | V2: =SUM(J2:U2) | W2: Non Interco Brkg Comm Renewal
A3: A5229 | B3: Alhpa Climbers | U3: 3070.18 | V3: =SUM(J3:U3) | W3: Non Interco Brkg Comm Renewal
A4: A5234 | B4: Another Motsatsi Investments (Pty) Ltd | C4: 00298626 | D4: 45352 | E4: 45352 | F4: 177893.12 | G4: 22236.64 | H4: 0 | I4: 0 | L4: 22236.64 | P4: 34178.55 | V4: =SUM(J4:U4) | W4: Non Interco Brkg Comm Renewal
A5: A4988 | B5: Antya Investment (Pty) Ltd | C5: 00302643 | D5: 45496 | E5: 45474 | F5: 2279.61 | G5: 455.92 | H5: 0 | I5: 0 | P5: 455.92 | V5: =SUM(J5:U5) | W5: Non Interco Brkg Comm Renewal
A6: A2203 | B6: Aon Preservation Fund | S6: 4518 | V6: =SUM(J6:U6) | W6: Non Interco Brkg Comm Renewal
A7: A5077 | B7: Aramex Botswana (Pty) Ltd | C7: 00299411 | D7: 45377 | E7: 45352 | F7: 35198.02 | G7: 4399.75 | H7: 0 | I7: 0 | L7: 19051.47 | V7: =SUM(J7:U7) | W7: Non Interco Brkg Comm Renewal
A8: A0486 | B8: Associated Fund Administrators (Pty) Ltd | Q8: 19980.24 | S8: 130000 | V8: =SUM(J8:U8) | W8: Non Interco Brkg Comm Renewal
A9: A5231 | B9: Astounding Solutions (Pty) Ltd | C9: 00297034 | D9: 45299 | E9: 45292 | F9: 3658.62 | G9: 731.72 | H9: 0 | I9: 0 | J9: 731.72 | K9: 731.72 | L9: 731.72 | M9: 731.72 | N9: 731.72 | O9: 731.72 | P9: 731.72 | Q9: 731.72 | R9: 731.72 | S9: 731.72 | T9: 731.72 | U9: 731.72 | V9: =SUM(J9:U9) | W9: Non Interco Brkg Comm Renewal
A10: E4780 | B10: Barloword Equipment Botswana (Pty) Ltd | C10: 00301163 | D10: 45447 | E10: 45444 | F10: 13596.49 | G10: 2719.3 | H10: 0 | I10: 0 | O10: 262600 | V10: =SUM(J10:U10) | W10: Non Interco Brkg Comm Renewal
A11: B5340 | B11: BIHL Defined Contribution Retirement Fund | C11: 00297961 | D11: 45327 | E11: 45292 | F11: 15131.58 | G11: 3026.32 | H11: 0 | I11: 0 | J11: 3026.32 | V11: =SUM(J11:U11) | W11: Non Interco Brkg Comm Renewal
A12: B5280 | B12: BIHL Insurance Company | C12: 00297856 | D12: 45323 | E12: 45322 | F12: 912.45 | G12: 182.49 | H12: 0 | I12: 0 | Q12: 30852.83 | V12: =SUM(J12:U12) | W12: Non Interco Brkg Comm Renewal
A13: B5447 | B13: BOMaid | C13: 00297740 | D13: 45320 | E13: 45292 | F13: 166027.09 | G13: 33205.42 | H13: 0 | I13: 0 | J13: 56000 | V13: =SUM(J13:U13) | W13: Non Interco Brkg Comm Renewal
A14: B1044 | B14: Botswana Accountancy College | C14: 00297128 | D14: 45301 | E14: 45292 | F14: 508367.69 | G14: 101673.54 | H14: 0 | I14: 0 | J14: 30000 | V14: =SUM(J14:U14) | W14: Non Interco Brkg Comm Renewal
A15: B5253 | B15: Botswana Bureau of Standards | C15: 00299630 | D15: 45390 | E15: 45383 | F15: 13873.99 | G15: 2774.8 | H15: 0 | I15: 0 | M15: 2774.8 | V15: =SUM(J15:U15) | W15: Non Interco Brkg Comm Renewal
A16: B4976 | B16: Botswana Communications Regulatory Authority | C16: 00299802 | D16: 45394 | E16: 45383 | F16: 12105.26 | G16: 2421.05 | H16: 0 | I16: 0 | M16: 2421.05 | V16: =SUM(J16:U16) | W16: Non Interco Brkg Comm Renewal
A17: B5599 | B17: Botswana Energy Regulatory Authority | C17: 00298314 | D17: 45341 | E17: 45323 | F17: 137560.28 | G17: 27512.06 | H17: 0 | I17: 0 | K17: 18223.31 | V17: =SUM(J17:U17) | W17: Non Interco Brkg Comm Renewal
A18: B5074 | B18: Botswana Examinations Council | C18: 00303599 | D18: 45530 | E18: 45505 | F18: 129736.11 | G18: 16217.01 | H18: 0 | I18: 0 | Q18: 98283.34 | V18: =SUM(J18:U18) | W18: Non Interco Brkg Comm Renewal
A19: B5168 | B19: Botswana Housing Corporation Staff Pension Fund | C19: 00299208 | D19: 45372 | E19: 45383 | F19: 8106.34 | G19: 1621.27 | H19: 0 | I19: 0 | M19: 1621.27 | V19: =SUM(J19:U19) | W19: Non Interco Brkg Comm Renewal
A20: B5614 | B20: Botswana Institute for Technology Research and Innovation | C20: 00299531 | D20: 45385 | E20: 45383 | F20: 684867.19 | G20: 136973.44 | H20: 0 | I20: 0 | M20: 100000 | V20: =SUM(J20:U20) | W20: Non Interco Brkg Comm Renewal
A21: B1988 | B21: Botswana Insurance Fund Management | C21: 00302939 | D21: 45506 | E21: 45505 | F21: 138481.02 | G21: 27696.2 | H21: 0 | I21: 0 | Q21: 39187.59 | V21: =SUM(J21:U21) | W21: Non Interco Brkg Comm Renewal
A22: B5211 | B22: Botswana Insurance Holdings Limited | C22: 00303051 | D22: 45510 | E22: 45505 | F22: 150520.2 | G22: 30104.04 | H22: 0 | I22: 0 | Q22: 40858.67 | V22: =SUM(J22:U22) | W22: Non Interco Brkg Comm Renewal
A23: L5011 | B23: Botswana Life Insurance Limited | C23: 00303590 | D23: 45530 | E23: 45505 | F23: 479334.88 | G23: 95866.98 | H23: 0 | I23: 0 | Q23: 123611 | V23: =SUM(J23:U23) | W23: Non Interco Brkg Comm Renewal
A24: B5017 | B24: Botswana Meat Commission | C24: 00301612 | D24: 45460 | E24: 45460 | F24: 6380.17 | G24: 1276.03 | H24: 0 | I24: 0 | O24: 1276.03 | S24: 3301.11 | V24: =SUM(J24:U24) | W24: Non Interco Brkg Comm Renewal
A25: B5367 | B25: Botswana Oil Limited | C25: 00297074 | D25: 45300 | E25: 45205 | F25: 253564.68 | G25: 50712.94 | H25: 0 | I25: 0 | J25: 0 | V25: =SUM(J25:U25) | W25: Non Interco Brkg Comm Renewal
A26: B5301 | B26: Botswana Open University | C26: 00299810 | D26: 45394 | E26: 45383 | F26: 9026.32 | G26: 1805.26 | H26: 0 | I26: 0 | M26: 40000 | V26: =SUM(J26:U26) | W26: Non Interco Brkg Comm Renewal
A27: B5328 | B27: Botswana Postal Services | C27: 00298871 | D27: 45364 | E27: 45383 | F27: 13690.44 | G27: 2738.09 | H27: 0 | I27: 0 | M27: 2738.09 | V27: =SUM(J27:U27) | W27: Non Interco Brkg Comm Renewal
A28: B4858 | B28: Botswana Public Officers Medical Aid Scheme | C28: 00299569 | D28: 45387 | E28: 45383 | F28: 33832.77 | G28: 4229.1 | H28: 0 | I28: 0 | M28: 106216.13 | V28: =SUM(J28:U28) | W28: Non Interco Brkg Comm Renewal
A29: B5288 | B29: Botswana Railways | C29: 00301610 | D29: 45460 | E29: 45383 | F29: 14815.16 | G29: 2963.03 | H29: 0 | I29: 0 | M29: 2963.03 | T29: 0 | V29: =SUM(J29:U29) | W29: Non Interco Brkg Comm Renewal
A30: B4903 | B30: Botswana Stock Exchange | C30: 00297159 | D30: 45302 | E30: 45292 | F30: 103768.35 | G30: 20753.67 | H30: 0 | I30: 0 | J30: 31133.88 | V30: =SUM(J30:U30) | W30: Non Interco Brkg Comm Renewal
A31: B5018 | B31: Botswana Tourism Organization | C31: 00299682 | D31: 45391 | E31: 45383 | F31: 182034.62 | G31: 36406.92 | H31: 0 | I31: 0 | M31: 74390.11 | V31: =SUM(J31:U31) | W31: Non Interco Brkg Comm Renewal
A32: B5464 | B32: Botswana Trade Commission | C32: 00299557 | D32: 45386 | E32: 45383 | F32: 70554.23 | G32: 8819.28 | H32: 0 | I32: 0 | M32: 23570.75 | V32: =SUM(J32:U32) | W32: Non Interco Brkg Comm Renewal
A33: B5735 | B33: BRECKWICK HOLDINGS | C33: 00303034 | D33: 45510 | E33: 45510 | F33: 0 | G33: 0 | H33: 38698.77 | I33: 0 | O33: 30553.26 | V33: =SUM(J33:U33) | W33: Non Interco Brkg Comm Renewal
A34: C4946 | B34: Car Rentals Botswana (Pty) Ltd | C34: 00301188 | D34: 45448 | E34: 45444 | F34: 8596.49 | G34: 1719.3 | H34: 0 | I34: 0 | O34: 27843.07 | V34: =SUM(J34:U34) | W34: Non Interco Brkg Comm Renewal
A35: C5187 | B35: Cash Bazaar Holdings( Pty) Ltd - Industrial Division | C35: 00303473 | D35: 45523 | E35: 45505 | F35: 219298.25 | G35: 43859.65 | H35: 0 | I35: 0 | Q35: 24877.28 | V35: =SUM(J35:U35) | W35: Non Interco Brkg Comm Renewal
A36: C5040 | B36: Cash Bazaar Holdings | C36: 00303449 | D36: 45520 | E36: 45505 | F36: 645124.71 | G36: 129024.94 | H36: 0 | I36: 0 | Q36: 164416.25 | V36: =SUM(J36:U36) | W36: Non Interco Brkg Comm Renewal
A37: C5188 | B37: Cash Bazaar Holdings | C37: 00303452 | D37: 45520 | E37: 45505 | F37: 383887.51 | G37: 76777.5 | H37: 0 | I37: 0 | Q37: 86052.64 | V37: =SUM(J37:U37) | W37: Non Interco Brkg Comm Renewal
A38: H4885 | B38: Cash Bazaar Holdings | C38: 00303456 | D38: 45520 | E38: 45505 | F38: 1153945.7 | G38: 230789.13 | H38: 0 | I38: 0 | Q38: 267951.66 | V38: =SUM(J38:U38) | W38: Non Interco Brkg Comm Renewal
A39: I4667 | B39: Cash Bazaar Holdings | C39: 00303458 | D39: 45520 | E39: 45505 | F39: 197575.66 | G39: 39515.13 | H39: 0 | I39: 0 | Q39: 39515.13 | V39: =SUM(J39:U39) | W39: Non Interco Brkg Comm Renewal
A40: M6904 | B40: Cash Bazaar Holdings | C40: 00303459 | D40: 45520 | E40: 45505 | F40: 204812.58 | G40: 40962.52 | H40: 0 | I40: 0 | Q40: 45129.68 | V40: =SUM(J40:U40) | W40: Non Interco Brkg Comm Renewal
...

Sheet Revenue walk Retail
A1: Revenue walk
A2: AON GROUP excl Exit | R2: Plug in Retail headoffice cost centre
A3: =SIB_Retail_details_R!B28 | B3: =SIB_Retail_details_R!C28 | E3: =SUM(C5:E5) | J3: =SUM(F5:J5) | Q3: =SUM(P5:Q5)
A4: ='[14]Revenue walk (Brk)'!A4 | C4: =SIB_Retail_details_R!C10 | D4: =SIB_Retail_details_R!C9 | E4: =SIB_Retail_details_R!C8 | F4: =SIB_Retail_details_R!C3 | G4: =SIB_Retail_details_R!C4 | H4: =SIB_Retail_details_R!C7 | I4: =SIB_Retail_details_R!C5 | J4: =SIB_Retail_details_R!C6 | R4: =CONCATENATE(A3," 2017"," update")
A5: =SIB_Retail_details_R!D28 | C5: =VLOOKUP(C4,SIB_Retail_details_R!$C$3:$E$17,3,FALSE) | D5: =VLOOKUP(D4,SIB_Retail_details_R!$C$3:$E$17,3,FALSE) | E5: =VLOOKUP(E4,SIB_Retail_details_R!$C$3:$E$17,3,FALSE) | F5: =VLOOKUP(F4,SIB_Retail_details_R!$C$3:$E$17,3,FALSE) | G5: =VLOOKUP(G4,SIB_Retail_details_R!$C$3:$E$17,3,FALSE) | H5: =VLOOKUP(H4,SIB_Retail_details_R!$C$3:$E$17,3,FALSE) | I5: =VLOOKUP(I4,SIB_Retail_details_R!$C$3:$E$17,3,FALSE) | J5: =VLOOKUP(J4,SIB_Retail_details_R!$C$3:$E$17,3,FALSE) | R5: =SIB_Retail_details_R!E28 | S5: =SUM(A5:Q5)-R5
A9: =A4 | B9: =A5
A10: =C4 | B10: =C5
A11: =D4 | B11: =D5
A12: =E4 | B12: =E5
A13: =F4 | B13: =F5
A14: =G4 | B14: =G5
A15: =H4 | B15: =H5
A16: =I4 | B16: =I5
A17: =J4 | B17: =J5
A18: =R4 | B18: =R5 | C18: =SUM(B9:B17)-B18
B24: Claims Outsourced | C24: New new positions
B25: Retail Restructure | C25: Replacement positions
B26: Broking Restructure | C26: Employee transfers
B27: CFC out

Sheet SIB_Retail_details_R
D2: Headcount | E2: Value
C3: NET EMPLOYEE TRANSFERS | E3: =SUMIF(J:J,C3,F:F)
C4: NET SALARY CHANGES | E4: =SUMIF(J:J,C4,F:F)
C5: NEW POSITIONS '16 | E5: =SUMIF(J:J,C5,F:F)
C6: NEW POSITIONS '17 | E6: =SUMIF(J:J,C6,F:F)
C7: REPLACEMENTS '16 | E7: =SUMIF(J:J,C7,F:F)
C8: RESTRUCTURING '16 | E8: =SUMIF(J:J,C8,F:F)
B9: Add further details here | C9: SEPARATIONS - INVOLUNTARY | E9: =SUMIF(J:J,C9,F:F)
C10: SEPARATIONS - VOLUNTARY | E10: =SUMIF(J:J,C10,F:F)
E11: =SUMIF(J:J,C11,F:F)
A18: [Begin Format Range] | G18: aon prd:Payroll
A19: 0 | G19: 2016
A20: 1 | G20: Annual
A21: 2 | G21: Actual
A22: 3 | G22: unspecified department
A23: D
A24: N
A25: [End Format Range]
B26: aon prd:Payroll:1
B28: RETAIL | C28: 2016 - 2017 | D28: =SUM(D$34:D$1048576) | E28: =SUM(E$34:E$1048576) | F28: =SUM(F$34:F$1048576)
D30: dec YTD | E30: dec YTD
B31: Department | C31: EE | D31: 42370.083 | E31: 42736.083
D32: Working Forecast | E32: Working Budget
B33: =B31 | C33: =C31 | D33: TMP Perm | E33: Permanent TCTC | F33: Variance | G33: Start Date | H33: Termination Date | I33: Group | J33: Reasons
A34: N | B34: 67891 - Hewitt McLagan | C34: 263313 - TYRONE BRUCE JANSEN | G34: 20140901 | J34: =IFERROR(VLOOKUP(C34,Lynette!$C$13:$D$1213,2,FALSE),0) | K34: =E34/D34-1
A35: N | B35: 67852 - Healthcare Operations | C35: 120102 - CLAUDIA LAHOUD | G35: 19950201 | J35: =IFERROR(VLOOKUP(C35,Lynette!$C$13:$D$1213,2,FALSE),0) | K35: =E35/D35-1
A36: N | B36: 67852 - Healthcare Operations | C36: 140502 - JACQUELINE NEL | G36: 19910601 | J36: =IFERROR(VLOOKUP(C36,Lynette!$C$13:$D$1213,2,FALSE),0) | K36: =E36/D36-1
A37: N | B37: 67852 - Healthcare Operations | C37: 262434 - ANNAKE PEARCE | G37: 20120401 | J37: =IFERROR(VLOOKUP(C37,Lynette!$C$13:$D$1213,2,FALSE),0) | K37: =E37/D37-1
A38: N | B38: 67852 - Healthcare Operations | C38: 262608 - GAVIN JOHN GRIFFIN | G38: 20130102 | J38: =IFERROR(VLOOKUP(C38,Lynette!$C$13:$D$1213,2,FALSE),0) | K38: =E38/D38-1
A39: N | B39: 67853 - Healthcare Bloemfontein | C39: 220537 - ANILIA BOSHOFF | G39: 20090401 | J39: =IFERROR(VLOOKUP(C39,Lynette!$C$13:$D$1213,2,FALSE),0) | K39: =E39/D39-1
A40: N | B40: 67853 - Healthcare Bloemfontein | C40: 220554 - HELEN VAN HEERDEN | G40: 20110201 | J40: =IFERROR(VLOOKUP(C40,Lynette!$C$13:$D$1213,2,FALSE),0) | K40: =E40/D40-1
A41: N | B41: 67853 - Healthcare Bloemfontein | C41: 263195 - LEONIE FOURIE | G41: 20140501 | J41: =IFERROR(VLOOKUP(C41,Lynette!$C$13:$D$1213,2,FALSE),0) | K41: =E41/D41-1
A42: N | B42: 67854 - Healthcare Cape Town | C42: 220110 - MARGAUX VAN HUYSSTEEN | G42: 20010618 | J42: =IFERROR(VLOOKUP(C42,Lynette!$C$13:$D$1213,2,FALSE),0) | K42: =E42/D42-1
A43: N | B43: 67854 - Healthcare Cape Town | C43: 260001 - VALENTINO YOUNG | G43: 20090316 | J43: =IFERROR(VLOOKUP(C43,Lynette!$C$13:$D$1213,2,FALSE),0) | K43: =E43/D43-1
A44: N | B44: 67854 - Healthcare Cape Town | C44: 263398 - ANTON EUGENE FOSTER | G44: 20141223 | J44: =IFERROR(VLOOKUP(C44,Lynette!$C$13:$D$1213,2,FALSE),0) | K44: =E44/D44-1
A45: N | B45: 67854 - Healthcare Cape Town | C45: 263625 - PORTIA LINN MOEN | G45: 20151101 | J45: =IFERROR(VLOOKUP(C45,Lynette!$C$13:$D$1213,2,FALSE),0) | K45: =E45/D45-1
... A47: N | B47: 67854 - Healthcare Cape Town | C47: 61821 - CHANTEL FRITZ | G47: 20110101 | J47: =IFERROR(VLOOKUP(C47,Lynette!$C$13:$D$1213,2,FALSE),0) | K47: =E47/D47-1
A48: N | B48: 67854 - Healthcare Cape Town | C48: New 1 | J48: =IFERROR(VLOOKUP(C48,Lynette!$C$13:$D$1213,2,FALSE),0) | K48: =E48/D48-1
A49: N | B49: 67855 - Healthcare Durban | C49: 130307 - LUTHANDO MRWEBI | G49: 20110301 | H49: 20160520 | J49: =IFERROR(VLOOKUP(C49,Lynette!$C$13:$D$1213,2,FALSE),0) | K49: =E49/D49-1
A50: N | B50: 67855 - Healthcare Durban | C50: 161800 - FRANK ADRIAN PREEN | G50: 20060223 | J50: =IFERROR(VLOOKUP(C50,Lynette!$C$13:$D$1213,2,FALSE),0) | K50: =E50/D50-1
...

Sheet Lynette
B1: AON PRD:PAYROLL
B2: ACTUAL | C2: CHECK
B3: 2016
B4: ANNUAL
B5: UNSPECIFIED DEPARTMENT
A9: BUSINESS UNIT | B9: DEPARTMENT | C9: EMPLOYEE CODE - NAME & SURNAME | D9: CLASSIFICATION
A11: BUSINESS UNIT | B11: DEPARTMENT | C11: EMPLOYEE CODE - NAME & SURNAME | D11: CLASSIFICATION
A12: EMPLOYEE BENEFITS
A13: EMPLOYEE BENEFITS | B13: 67862 - SERVICE SSC | C13: 11411 - SHAAHIDA ADAMS | D13: NET SALARY CHANGES
A14: EMPLOYEE BENEFITS | B14: 67852 - HEALTHCARE OPERATIONS | C14: 120102 - CLAUDIA LAHOUD | D14: NET SALARY CHANGES
A15: EMPLOYEE BENEFITS | B15: 67865 - HEALTHCARE TEAM3 | C15: 120110 - CELESTE AQUALINE LAWRENCE | D15: NET SALARY CHANGES
A16: EMPLOYEE BENEFITS | B16: 67874 - RF CONSULTING | C16: 130117 - JOHANNES MAKGOBELA | D16: NET SALARY CHANGES
A17: EMPLOYEE BENEFITS | B17: 67866 - HEALTHCARE TEAM4 | C17: 130142 - THULANI GIDEON MABENA | D17: '16
A18: EMPLOYEE BENEFITS | B18: 67855 - HEALTHCARE DURBAN | C18: 130307 - LUTHANDO MRWEBI | D18: SEPARATIONS - VOLUNTARY '16
A19: EMPLOYEE BENEFITS | B19: 67879 - QED PENSIONS | C19: 130314 - LILLIAN NEO MOAGI | D19: '16
A20: EMPLOYEE BENEFITS | B20: 67852 - HEALTHCARE OPERATIONS | C20: 140502 - JACQUELINE NEL | D20: NET SALARY CHANGES
A21: EMPLOYEE BENEFITS | B21: 67874 - RF CONSULTING | C21: 141106 - IGNATIUS NDLOVU | D21: NET SALARY CHANGES
A22: EMPLOYEE BENEFITS | B22: 67855 - HEALTHCARE DURBAN | C22: 141149 - NOSIPHO PORTIA NGXULELO | D22: '16
A23: EMPLOYEE BENEFITS | B23: 67865 - HEALTHCARE TEAM3 | C23: 151601 - BRENDA OPPERMAN | D23: NET SALARY CHANGES
A24: EMPLOYEE BENEFITS | B24: 67858 - HEALTH RISK MANAGEMENT | C24: 151608 - CHRISTINE CHARLOTTE OOSTHUIZEN | D24: NET SALARY CHANGES
... A161: EMPLOYEE BENEFITS | B161: 67885 - THE BENEFIT SOLUTION | C161: NEW 2 | D161: '16
A162: HEWITT EXIT
A163: HEWITT EXIT | B163: 67886 - RETIREMENT FUNDING FUTURE SALE | C163: 100129 - LEVERNE LAYLAHNE JAPPIE | D163: '16
A164: HEWITT EXIT | B164: 67887 - HEADOFFCE FUTURE SALE BUSINESS | C164: 1013 - VIRGINIA PODILE | D164: '16
A165: HEWITT EXIT | B165: 67886 - RETIREMENT FUNDING FUTURE SALE | C165: 11419 - JAMES JOSEPH ADAMS | D165: '16
A166: HEWITT EXIT | B166: 67886 - RETIREMENT FUNDING FUTURE SALE | C166: 130271 - BERESFORD LOUIS MARTIN | D166: '16
A167: HEWITT EXIT | B167: 67886 - RETIREMENT FUNDING FUTURE SALE | C167: 130292 - NKANYISO MPOFU | D167: '16
A168: HEWITT EXIT | B168: 67886 - RETIREMENT FUNDING FUTURE SALE | C168: 141101 - DIJON NKOMO | D168: '16
A169: HEWITT EXIT | B169: 67886 - RETIREMENT FUNDING FUTURE SALE | C169: 141123 - PETRONELLA ZANELE NKONYANE | D169: '16
A170: HEWITT EXIT | B170: 67886 - RETIREMENT FUNDING FUTURE SALE | C170: 180101 - GLENELG KABELO RAKALE | D170: '16
A171: HEWITT EXIT | B171: 67887 - HEADOFFCE FUTURE SALE BUSINESS | C171: 181547 - AIFHELI EDWARDS RAMBAU | D171: '16
A172: HEWITT EXIT | B172: 67886 - RETIREMENT FUNDING FUTURE SALE | C172: 181550 - NORMA GAIL RODRIGUES | D172: '16
A173: HEWITT EXIT | B173: 67886 - RETIREMENT FUNDING FUTURE SALE | C173: 181563 - REFILOE RELEBOHILE PALESA TINTE | D173: '16
A174: HEWITT EXIT | B174: 67886 - RETIREMENT FUNDING FUTURE SALE | C174: 190119 - MARCIA MARGARET JOHNSON | D174: '16
... A212: HEWITT EXIT | B212: 67886 - RETIREMENT FUNDING FUTURE SALE | C212: 151609 - BONITA OOSTHUIZEN | D212: '16
A213: RETAIL
A214: RETAIL | B214: 67754 - CORPORATE CAPE TOWN | C214: 100100 - GERDALENE JANSE VAN RENSBURG | D214: '16
A215: RETAIL | B215: 67787 - COMMERCIAL NEW CASTLE | C215: 100128 - MARIEET SUSANNA JACOBS | D215: NET SALARY CHANGES
A216: RETAIL | B216: 67780 - COMMERCIAL DURBAN | C216: 100132 - KESHINI JOSEPH | D216: NET SALARY CHANGES
A217: RETAIL | B217: 67785 - COMMERCIAL MAFIKENG | C217: 1016 - MAGGIE MIETA MATHIBE | D217: SEPARATIONS - INVOLUNTARY
...

Sheet KEY
G3: Break out = | J3: Also do a FTE (headcount)
C4: Add in mid term 2016 starters impact | G4: Restructure -
C5: Run rate impact | H5: Claims out | J5: new new | K5: per BU
H6: Retail out | J6: new replacement | K6: per BU
H7: Broking out | J7: transfers | K7: perhaps
H8: CFC out
H10: UNKNOWN LEAVER
H11: REPLACEMENTS
H12: SEPARATIONS - INVOLUNTARY
H13: NET SALARY CHANGES
H14: SEPARATIONS - VOLUNTARY
H15: NEW POSITIONS

Sheet Monthly2016
A1: CUBE: | B1: aon prd:Payroll
A2: aon prd:Year | B2: 2016
A3: aon prd:Version | B3: Working Forecast
C6: Jan | D6: Jan | E6: Feb | F6: Feb | G6: Mar | H6: Mar | I6: Apr | J6: Apr | K6: May | L6: May | M6: May | N6: Jun | O6: Jun | P6: Jul | Q6: Jul | R6: Jul | S6: Aug | T6: Aug | U6: Sep | V6: Sep | W6: Sep | X6: Oct | Y6: Oct | Z6: Oct | AA6: Nov | AB6: Nov | AC6: Dec | AD6: Dec | AE6: All Months | AF6: All Months | AG6: All Months
C7: Cash Component (D) | D7: Cash Component - Temp (D) | E7: Cash Component (D) | F7: Cash Component - Temp (D) | G7: Cash Component (D) | H7: Cash Component - Temp (D) | I7: Cash Component (D) | J7: Cash Component - Temp (D) | K7: Cash Component - Consultant (D) | L7: Cash Component (D) | M7: Cash Component - Temp (D) | N7: Cash Component (D) | O7: Cash Component - Temp (D) | P7: Cash Component - Consultant (D) | Q7: Cash Component (D) | R7: Cash Component - Temp (D) | S7: Cash Component (D) | T7: Cash Component - Temp (D) | U7: Cash Component - Consultant (D) | V7: Cash Component (D) | W7: Cash Component - Temp (D) | X7: Cash Component - Consultant (D) | Y7: Cash Component (D) | Z7: Cash Component - Temp (D) | AA7: Cash Component (D) | AB7: Cash Component - Temp (D) | AC7: Cash Component (D) | AD7: Cash Component - Temp (D) | AE7: Cash Component - Consultant (D) | AF7: Cash Component (D) | AG7: Cash Component - Temp (D) | AH7: Total
A8: 67891 - Hewitt McLagan | B8: 263313 - TYRONE BRUCE JANSEN | AH8: =SUM(AE8:AG8)
A9: 67852 - Healthcare Operations | B9: 120102 - CLAUDIA LAHOUD | AH9: =SUM(AE9:AG9)
A10: 67852 - Healthcare Operations | B10: 140502 - JACQUELINE NEL | AH10: =SUM(AE10:AG10)
A11: 67852 - Healthcare Operations | B11: 262434 - ANNAKE PEARCE | AH11: =SUM(AE11:AG11)
A12: 67852 - Healthcare Operations | B12: 262608 - GAVIN JOHN GRIFFIN | AH12: =SUM(AE12:AG12)
A13: 67852 - Healthcare Operations | B13: New 1 | AH13: =SUM(AE13:AG13)
A14: 67853 - Healthcare Bloemfontein | B14: 220537 - ANILIA BOSHOFF | AH14: =SUM(AE14:AG14)
A15: 67853 - Healthcare Bloemfontein | B15: 220554 - HELEN VAN HEERDEN | AH15: =SUM(AE15:AG15)
A16: 67853 - Healthcare Bloemfontein | B16: 263195 - LEONIE FOURIE | AH16: =SUM(AE16:AG16)
A17: 67854 - Healthcare Cape Town | B17: 220110 - MARGAUX VAN HUYSSTEEN | AH17: =SUM(AE17:AG17)
A18: 67854 - Healthcare Cape Town | B18: 260001 - VALENTINO YOUNG | AH18: =SUM(AE18:AG18)
A19: 67854 - Healthcare Cape Town | B19: 263398 - ANTON EUGENE FOSTER | AH19: =SUM(AE19:AG19)
... A101: GLOBAL BENEFITS (4200ZA) | B101: 262699 - THARANGANY SINGARAVELLOO | AH101: =SUM(AE101:AG101)

Sheet Monthly2017
C1: Annual | D1: Annual | E1: Annual | F1: Jan | G1: Jan | H1: Feb | I1: Feb | J1: Mar | K1: Mar | L1: Apr | M1: Apr | N1: May | O1: May | P1: Jun | Q1: Jun | R1: Jul | S1: Jul | T1: Aug | U1: Aug | V1: Sep | W1: Sep | X1: Oct | Y1: Oct | Z1: Nov | AA1: Nov | AB1: Dec | AC1: Dec | AD1: All Months | AE1: All Months
C2: Consultant TCTC | D2: Permanent TCTC | E2: Temp TCTC | F2: Permanent TCTC | G2: Temp TCTC | H2: Permanent TCTC | I2: Temp TCTC | J2: Permanent TCTC | K2: Temp TCTC | L2: Permanent TCTC | M2: Temp TCTC | N2: Permanent TCTC | O2: Temp TCTC | P2: Permanent TCTC | Q2: Temp TCTC | R2: Permanent TCTC | S2: Temp TCTC | T2: Permanent TCTC | U2: Temp TCTC | V2: Permanent TCTC | W2: Temp TCTC | X2: Permanent TCTC | Y2: Temp TCTC | Z2: Permanent TCTC | AA2: Temp TCTC | AB2: Permanent TCTC | AC2: Temp TCTC | AD2: Permanent TCTC | AE2: Temp TCTC | AF2: Total
A3: 67891 - Hewitt McLagan | B3: 263313 - TYRONE BRUCE JANSEN | AF3: =SUM(AD3:AE3)
A4: 67852 - Healthcare Operations | B4: 0 | AF4: =SUM(AD4:AE4)
A5: 67852 - Healthcare Operations | B5: 120102 - CLAUDIA LAHOUD | AF5: =SUM(AD5:AE5)
A6: 67852 - Healthcare Operations | B6: 140502 - JACQUELINE NEL | AF6: =SUM(AD6:AE6)
A7: 67852 - Healthcare Operations | B7: 262434 - ANNAKE PEARCE | AF7: =SUM(AD7:AE7)
A8: 67852 - Healthcare Operations | B8: 262608 - GAVIN JOHN GRIFFIN | AF8: =SUM(AD8:AE8)
A9: 67853 - Healthcare Bloemfontein | B9: 220537 - ANILIA BOSHOFF | AF9: =SUM(AD9:AE9)
A10: 67853 - Healthcare Bloemfontein | B10: 220554 - HELEN VAN HEERDEN | AF10: =SUM(AD10:AE10)
A11: 67853 - Healthcare Bloemfontein | B11: 263195 - LEONIE FOURIE | AF11: =SUM(AD11:AE11)
A12: 67854 - Healthcare Cape Town | B12: 220110 - MARGAUX VAN HUYSSTEEN | AF12: =SUM(AD12:AE12)
A13: 67854 - Healthcare Cape Town | B13: 260001 - VALENTINO YOUNG | AF13: =SUM(AD13:AE13)
A14: 67854 - Healthcare Cape Town | B14: 263398 - ANTON EUGENE FOSTER | AF14: =SUM(AD14:AE14)
... A86: GLOBAL BENEFITS (4200ZA) | B86: 262699 - THARANGANY SINGARAVELLOO | AF86: =SUM(AD86:AE86)

Sheet Sheet1
